<?xml version="1.0"?>
<robot name="planar_3dof" xmlns:xacro="http://ros.org/wiki/xacro">

  <material name="red">
    <color rgba="0.78 0.0 0.0 0.81"/>
  </material>
  <material name="grey">
    <color rgba="0.4 0.4 0.4 1.0" />
  </material>
  <material name="yellow">
    <color rgba="0.898 0.737 0.082 0.810"/>
  </material>
  <material name="white">
    <color rgba="1.0 1.0 1.0 0.0"/>
  </material>


  <link name="world" />

  <link name="base_link">
    <visual>
      <origin rpy="0 0 0" xyz="0 0 0" />
      <geometry>
        <cylinder length="0.1" radius="0.2" />
      </geometry>
      <material name="red">
        <color rgba="0.78 0.0 0.0 0.81"/>
      </material>
    </visual>
  <collision>
    <origin rpy="0 0 0" xyz="0 0 0" />
    <geometry>
      <cylinder length="0.1" radius="0.2" />
    </geometry>
    <material name="grey"/>
  </collision>
    
  </link>

  <joint name="fixed" type="fixed">
    <parent link="world" />
    <child link="base_link" />
  </joint>

  <link name="link_1">
    <visual>
      <geometry>
        <mesh filename="/home/toto/Robotics2-project/src/ocs2_robotic_assets/resources/mobile_manipulator/3R/meshes/visual/arm_link.stl" scale="1 1 1" />
      </geometry>
      <material name="white">
        <color rgba="1.0 1.0 1.0 0.0"/>
      </material>
    </visual>
    <collision>
      <origin rpy="0 1.5708 0" xyz="0.25 0 0" />
      <geometry>
        <cylinder length="0.5" radius="0.05" />
      </geometry>
      <material name="red"/>
    </collision>
    <inertial>
      <origin xyz="0.25 0 0" rpy="0 0 0" />
      <mass value="3.0" />
      <inertia ixx="0.00375" ixy="0.0" ixz="0.0" iyy="0.00375" iyz="0.0" izz="0.25" />
    </inertial>
  </link>
  <joint name="joint_1" type="revolute">
    <parent link="base_link" />
    <child link="link_1" />
    <origin xyz="0 0 0.05" rpy="0 0 0" />
    <axis xyz="0 0 1" />
    <limit effort="0" velocity="0.5" />
  </joint>

  <link name="link_2">
    <visual>
      <geometry>
        <mesh filename="/home/toto/Robotics2-project/src/ocs2_robotic_assets/resources/mobile_manipulator/3R/meshes/visual/arm_link.stl" scale="1 1 1" />
      </geometry>
      <material name="white">
        <color rgba="1.0 1.0 1.0 0.0"/>
      </material>
    </visual>
    <collision>
      <geometry>
        <mesh filename="/home/toto/Robotics2-project/src/ocs2_robotic_assets/resources/mobile_manipulator/3R/meshes/collision/arm_link.stl" scale="1 1 1" />
      </geometry>
      <material name="red"/>
    </collision>
    <inertial>
    <origin xyz="0.25 0 0" rpy="0 0 0" />
      <mass value="3.0" />
      <inertia ixx="0.00375" ixy="0.0" ixz="0.0" iyy="0.00375" iyz="0.0" izz="0.25" />
    </inertial>
  </link>

  <joint name="joint_2" type="revolute">
    <parent link="link_1" />
    <child link="link_2" />
    <origin xyz="0.5 0.0 0.0" rpy="0.0 0 0.0" />
    <axis xyz="0 0 1" />
    <limit effort="0" velocity="0.5" />
  </joint>

  <link name="gripper">
    <visual>
      <geometry>
        <mesh filename="/home/toto/Robotics2-project/src/ocs2_robotic_assets/resources/mobile_manipulator/3R/meshes/visual/arm_link.stl" scale="1 1 1" />
      </geometry>
      <material name="white">
        <color rgba="1.0 1.0 1.0 0.0"/>
      </material>
    </visual>
    <collision>
      <geometry>
        <mesh filename="/home/toto/Robotics2-project/src/ocs2_robotic_assets/resources/mobile_manipulator/3R/meshes/collision/gripper.stl" scale="1 1 1" />
      </geometry>
      <material name="grey"/>
    </collision>
    <inertial>
      <origin xyz="0.25 0 0" rpy="0 0 0" />
      <mass value="3.0" />
      <inertia ixx="0.00375" ixy="0.0" ixz="0.0" iyy="0.00375" iyz="0.0" izz="0.25" />
    </inertial>
  </link>

  <joint name="joint_3" type="revolute">
    <parent link="link_2" />
    <child link="gripper" />
    <origin xyz="0.5 0.0 0.0" rpy="0.0 0 0.0" />
    <axis xyz="0 0 1" />
    <limit effort="0" velocity="0.5" />
  </joint>

  <link name="end" >
    <visual>
      <geometry>
        <sphere radius="0.01" />
      </geometry>
      <material name="grey"/>
    </visual>
    <collision>
      <geometry>
        <sphere radius="0.01" />
      </geometry>
      <material name="grey"/>
    </collision>
    <inertial>
      <mass value="0.0" />
      <inertia ixx="0.000" ixy="0.0" ixz="0.0" iyy="0.000" iyz="0.0" izz="0.000" />
    </inertial>
  </link>

  <joint name="gripper_end" type="fixed">
    <parent link="gripper" />
    <child link="end" />
    <origin xyz="0.5 0 0" rpy="0 0 0" />
  </joint>

</robot>

